Workbook

Sheet Totals
B1: Seen | C1: Own
A2: 1920 | B2: =IFERROR(SUM(INDIRECT(ADDRESS(2,2,,,$A2)&":"&ADDRESS(1000,2))),0) -> 0 | C2: =IFERROR(SUM(INDIRECT(ADDRESS(2,3,,,$A2)&":"&ADDRESS(1000,3))),0) -> 0
A3: 1921 | B3: =IFERROR(SUM(INDIRECT(ADDRESS(2,2,,,$A3)&":"&ADDRESS(1000,2))),0) -> 0 | C3: =IFERROR(SUM(INDIRECT(ADDRESS(2,3,,,$A3)&":"&ADDRESS(1000,3))),0) -> 0
A4: 1922 | B4: =IFERROR(SUM(INDIRECT(ADDRESS(2,2,,,$A4)&":"&ADDRESS(1000,2))),0) -> 0 | C4: =IFERROR(SUM(INDIRECT(ADDRESS(2,3,,,$A4)&":"&ADDRESS(1000,3))),0) -> 0
A5: 1923 | B5: =IFERROR(SUM(INDIRECT(ADDRESS(2,2,,,$A5)&":"&ADDRESS(1000,2))),0) -> 0 | C5: =IFERROR(SUM(INDIRECT(ADDRESS(2,3,,,$A5)&":"&ADDRESS(1000,3))),0) -> 0
A6: 1924 | B6: =IFERROR(SUM(INDIRECT(ADDRESS(2,2,,,$A6)&":"&ADDRESS(1000,2))),0) -> 0 | C6: =IFERROR(SUM(INDIRECT(ADDRESS(2,3,,,$A6)&":"&ADDRESS(1000,3))),0) -> 0
A7: 1925 | B7: =IFERROR(SUM(INDIRECT(ADDRESS(2,2,,,$A7)&":"&ADDRESS(1000,2))),0) -> 0 | C7: =IFERROR(SUM(INDIRECT(ADDRESS(2,3,,,$A7)&":"&ADDRESS(1000,3))),0) -> 0
A8: 1926 | B8: =IFERROR(SUM(INDIRECT(ADDRESS(2,2,,,$A8)&":"&ADDRESS(1000,2))),0) -> 0 | C8: =IFERROR(SUM(INDIRECT(ADDRESS(2,3,,,$A8)&":"&ADDRESS(1000,3))),0) -> 0
A9: 1927 | B9: =IFERROR(SUM(INDIRECT(ADDRESS(2,2,,,$A9)&":"&ADDRESS(1000,2))),0) -> 0 | C9: =IFERROR(SUM(INDIRECT(ADDRESS(2,3,,,$A9)&":"&ADDRESS(1000,3))),0) -> 0
A10: 1928 | B10: =IFERROR(SUM(INDIRECT(ADDRESS(2,2,,,$A10)&":"&ADDRESS(1000,2))),0) -> 0 | C10: =IFERROR(SUM(INDIRECT(ADDRESS(2,3,,,$A10)&":"&ADDRESS(1000,3))),0) -> 0
A11: 1929 | B11: =IFERROR(SUM(INDIRECT(ADDRESS(2,2,,,$A11)&":"&ADDRESS(1000,2))),0) -> 0 | C11: =IFERROR(SUM(INDIRECT(ADDRESS(2,3,,,$A11)&":"&ADDRESS(1000,3))),0) -> 0
A12: 1930 | B12: =IFERROR(SUM(INDIRECT(ADDRESS(2,2,,,$A12)&":"&ADDRESS(1000,2))),0) -> 0 | C12: =IFERROR(SUM(INDIRECT(ADDRESS(2,3,,,$A12)&":"&ADDRESS(1000,3))),0) -> 0
A13: 1931 | B13: =IFERROR(SUM(INDIRECT(ADDRESS(2,2,,,$A13)&":"&ADDRESS(1000,2))),0) -> 0 | C13: =IFERROR(SUM(INDIRECT(ADDRESS(2,3,,,$A13)&":"&ADDRESS(1000,3))),0) -> 0
... A114: 2032 | B114: =IFERROR(SUM(INDIRECT(ADDRESS(2,2,,,$A114)&":"&ADDRESS(1000,2))),0) -> 0 | C114: =IFERROR(SUM(INDIRECT(ADDRESS(2,3,,,$A114)&":"&ADDRESS(1000,3))),0) -> 0

Sheet 2026
B1: Seen | C1: Own | D1: Want to see | E1: Where | F1: IMDb | G1: =SUM(B:B) -> 23 | H1: =_xlfn.CONCAT(SUM(C:C)," (",SUMPRODUCT(C:C,--(NOT(B:B=1))),")") -> 29 (21) | I1: 46192
A2: The Rip | D2: 1 | E2: Netflix | G2: en
A3: Joe's College Road Trip | E3: Netflix | G3: en
A4: War Machine | D4: 1 | E4: Netflix | G4: en
A5: Peaky Blinders: The Immortal Man | E5: Netflix | G5: en
A6: In the Blink of an Eye | E6: Hulu | G6: en
A7: The Wrecking Crew | D7: 1 | E7: Prime | G7: en
A8: Relationship Goals | E8: Prime | G8: en
A9: Love Me Love Me | E9: Prime | G9: en
A10: The Bluff | E10: Prime | G10: en
A11: The Mother and the Bear
A12: We Bury the Dead
A13: Greenland 2: Migration | B13: 1
A14: Primate | C14: 1 | D14: 1
A15: Dead Man's Wire
A16: I Was A Stranger
A17: Magellan | D17: 1
A18: My Neighbor Adolf
A19: OBEX
A20: People We Meet on Vacation | D20: 1
A21: Young Mothers
A22: 28 Years Later: The Bone Temple
A23: Charlie the Wonderdog
A24: All You Need Is Kill
A25: A Private Life
A26: Killer Whale
A27: Night Patrol
A28: Sound of Falling
A29: A Useful Ghost
A30: Clika
A31: H is for Hawk | D31: 1
A32: Mercy
A33: Return to Silent Hill
A34: In Cold Light
A35: Mel Brooks: The 99 Year Old Man! | D35: 1
A36: Hard Boiled
A37: Iron Lung
A38: Send Help | B38: 1
A39: Shelter | C39: 1 | D39: 1
A40: Worldbreaker
...

Sheet 2025
B1: Seen | C1: Own | D1: Want to see | E1: Where | F1: IMDb | G1: =SUM(B:B) -> 78 | H1: =_xlfn.CONCAT(SUM(C:C)," (",SUMPRODUCT(C:C,--(NOT(B:B=1))),")") -> 66 (25) | I1: 46387
A2: No Other Choice | D2: 10 | E2: 19.99 | F2: 7.6 | G2: ko | H2: After being laid off and humiliated by a ruthless job market, a veteran paper mill manager descends into violence in a desperate bid to reclaim his dignity.
A3: Sentimental Value | C3: 1 | D3: 9 | E3: Plex | F3: 7.9 | G3: no | H3: An intimate exploration of family, memories, and the reconciliatory power of art.
A4: Twinless | C4: 1 | D4: 8 | E4: Plex | F4: 7.5 | G4: en | H4: A young man grieving the loss of his twin brother joins a support group for "twinless twins."
A5: The Smashing Machine | C5: 1 | D5: 8 | E5: Hulu | F5: 6.7 | G5: en | H5: The true story of mixed martial arts and UFC fighter Mark Kerr, whose obsession with greatness made him a legend -- and nearly cost him everything.
A6: Together | C6: 1 | D6: 8 | E6: Plex | F6: 6.7 | G6: en | H6: With a move to the countryside already testing the limits of a couple's relationship, a supernatural encounter begins an extreme transformation of their love, their lives, and their flesh.
A7: Blue Moon | D7: 8 | E7: 20.95 | F7: 7.3 | G7: en | H7: On the evening of March 31, 1943, legendary lyricist Lorenz Hart confronts his shattered self-confidence in Sardi’s bar as his former collaborator Richard Rodgers celebrates the opening night of his ground-breaking hit musical “Oklahoma!”.
A8: Ballad of a Small Player | D8: 8 | E8: Netflix | F8: 5.8 | G8: en | H8: Amid the glittering casinos of Macau, a gambler running from his past — and his debts — becomes fascinated by an enigmatic woman at the baccarat table.
A9: I'm Still Here | C9: 1 | D9: 7 | E9: Plex | F9: 8.1 | G9: pt | H9: A woman married to a former politician during the 1971 military dictatorship in Brazil is forced to reinvent herself and chart a new course for her family after a violent and arbitrary act.
A10: Song Sung Blue | C10: 1 | D10: 7 | E10: Plex | F10: 7.5 | G10: en | H10: After meeting at a gig for musical impersonators, Mike and Claire decide to form a Neil Diamond tribute act. They grow closer through their rehearsals, and despite their separate years of hurt and disappointments, they fall in love and begin touring together. The couple form the band “Thunder & Lightning” and take their infectious energy across the country.
A11: If I Had Legs I'd Kick You | C11: 1 | D11: 7 | E11: Plex | F11: 7.3 | G11: en | H11: With her life crashing down around her, Linda attempts to navigate her child's mysterious illness, her absent husband, a missing person, and an increasingly hostile relationship with her therapist.
A12: Bring Her Back | C12: 1 | D12: 7 | E12: Plex | F12: 7.2 | G12: en | H12: Following the death of their father, a brother and sister are sent to live with a foster mother, only to learn that she is hiding a terrifying secret.
A13: Eden | C13: 1 | D13: 7 | E13: Plex | F13: 6.5 | G13: en | H13: A group of disillusioned outsiders abandon modern society in search of a new beginning. Settling on a remote, uninhabited island, their utopian dream quickly unravels as they discover that the greatest threat isn’t the brutal climate or deadly wildlife, but each other.
A14: Good Boy | C14: 1 | D14: 7 | F14: 6.2 | G14: en | H14: A loyal dog moves to a rural family home with his owner Todd, only to discover supernatural forces lurking in the shadows. As dark entities threaten his human companion, the brave pup must fight to protect the one he loves most.
A15: Truth & Treason | C15: 1 | D15: 7 | E15: Plex | G15: en
A16: Don't Let's Go to the Dogs Tonight | D16: 7 | E16: Netflix | F16: 6.9 | G16: en | H16: Depicts 8-year-old Bobo's life on her family's Rhodesian farm during the Bush War's final stages. It explores the family's bond with Africa's land and the war's impact on the region and individuals through Bobo's perspective.
A17: Arco | D17: 7
A18: Relay | C18: 1 | D18: 6 | E18: Plex | F18: 7 | G18: en | H18: A broker of lucrative payoffs between corrupt corporations and the individuals who threaten them breaks his own rules when a new client seeks his protection to stay alive.
A19: Materialists | C19: 1 | D19: 6 | E19: Plex | F19: 6.3 | G19: en | H19: An ambitious young New York City matchmaker finds herself torn between the perfect match and her imperfect ex.
A20: Drop | C20: 1 | D20: 6 | E20: Plex | F20: 6.1 | G20: en | H20: A widowed mother's first date in years takes a terrifying turn when she's bombarded with anonymous threatening messages on her phone during their upscale dinner, leaving her questioning if her charming date is behind the harassment.
A21: The Wilderness | D21: 6 | E21: 7.99 | F21: 8.2 | G21: en | H21: Kidnapped and abandoned in the Utah desert, a group of troubled boys are forced into a ruthless "Wilderness Therapy" program. Cut off from the world, they must survive both the elements and the mind games of a director who may not be trying to save them at all.
A22: Clemente | D22: 6 | E22: 12.99 | F22: 8.2 | G22: en | H22: An immersive documentary about the remarkable life and legacy of MLB icon Roberto Clemente.
A23: The History of Sound | D23: 6 | E23: 21.69 | F23: 6.9 | G23: en | H23: In 1917, two young music students attending the Boston Conservatory bond over their mutual love of folk music. They reconnect a few years later, embarking on a song collecting trip in the backwaters of Maine.
A24: Die My Love | D24: 6 | E24: 26.99 | F24: 6.5 | G24: en | H24: Grace, a writer and young mother, is slowly slipping into madness. Locked away in an old house in Montana, her increasingly agitated and erratic behaviour leaves her companion, Jackson, worried and helpless.
A25: Black Phone 2 | C25: 1 | D25: 5 | E25: Plex | F25: 6.6 | G25: en | H25: Four years after escaping The Grabber, Finney Blake is struggling with his life after captivity. When his sister Gwen begins receiving calls in her dreams from the black phone and seeing disturbing visions of three boys being stalked at a winter camp, the siblings become determined to solve the mystery and confront a killer who has grown more powerful in death and more significant to them than either could imagine.
A26: Dust Bunny | C26: 1 | D26: 5 | E26: Plex
A27: John Candy: I Like Me | D27: 5 | E27: Prime | F27: 8.1 | G27: en | H27: From director Colin Hanks and producer Ryan Reynolds--both lifelong John Candy fans--comes John Candy: I Like Me, an exploration of the life and legacy of the comedic icon. The film showcases Candy's remarkable career, from his breakout turn on SCTV in his beloved native Canada to starring in some of the biggest comedies of all time. But it also delves deeply into Candy's life off-camera, through never-before-seen home videos and the personal recollections of those who knew him best. A remarkable roster of family members, close friends and colleagues share their memories of John Candy, creating an intimate and indelible portrait of an unforgettable talent who helped define a cinematic era. John Candy: I Like Me tells the story of a son, husband, father, friend, and star, driven to bring joy to audiences and loved ones while battling personal ghosts and Hollywood pressures.
A28: Re-Election | D28: 5 | E28: 7.99 | F28: 7.9 | G28: en | H28: A wry, warm, and witty coming of (middle) age comedy, RE-ELECTION follows a 40-something underdog who returns to high school to reboot his past and finally win the race for class president.
A29: Little Amélie or the Character of Rain | D29: 5 | E29: 22.99 | F29: 7.6 | G29: fr | H29: The world is a perplexing, peaceful mystery to Amélie until a miraculous encounter with chocolate ignites her wild sense of curiosity. As she develops a deep attachment to her family's housekeeper, Nishio-san, Amélie discovers the wonders of nature as well as the emotional truths hidden beneath the surface of her family's idyllic life as foreigners in post-war Japan.
A30: Secret Mall Apartment | D30: 5 | E30: Paramount | F30: 7.2 | G30: en | H30: A struggling young dancer finds herself drawn in by dark forces when a peculiar, well-connected older couple promise her a shot at fame.
A31: The Perfect Neighbor | D31: 5 | E31: Netflix | F31: 7.1 | G31: en | H31: Police bodycam footage reveals how a long-running neighborhood dispute turned fatal in this documentary about fear, prejudice and Stand Your Ground laws.
A32: Lurker | D32: 5 | E32: 25.89 | F32: 6.9 | G32: en | H32: When a twenty-something retail clerk meets a rising popstar, he takes the opportunity to edge his way into the in-crowd. But as the line between friend and fan blurs beyond recognition, access and proximity become a matter of life and death.
A33: Waltzing with Brando | D33: 5 | E33: 14.99 | F33: 6.7 | G33: en | H33: The story of how Marlon Brando plucked Bernard Judge, an obscure but idealistic Los Angeles architect from his stable existence and convinced him that he should build the world’s first ecologically perfect retreat on a tiny and uninhabitable Tahitian island.
A34: Christy | D34: 5 | E34: 19.98 | F34: 6.2 | G34: en | H34: Christy Martin never imagined life beyond her small-town roots in West Virginia—until she discovered a knack for punching people. Fueled by grit, raw determination, and an unshakable desire to win, she charges into the world of boxing under the guidance of her trainer and manager-turned-husband, Jim. But while Christy flaunts a fiery persona in the ring, her toughest battles unfold outside it—confronting family, identity, and a relationship that just might become life-or-death.
A35: The Luckiest Man in America | D35: 5 | E35: Hulu | F35: 6.2 | G35: en | H35: May 1984. An unemployed ice cream truck driver steps onto the game show Press Your Luck harboring a secret: the key to endless money. But his winning streak is threatened when the bewildered executives uncover his real motivations.
A36: Regretting You | D36: 5 | E36: Paramount | F36: 6.2 | G36: en | H36: Morgan Grant and her daughter Clara explore what's left behind after a devastating accident reveals a shocking betrayal and forces them to confront family secrets, redefine love, and rediscover each other.
A37: Bring Them Down | C37: 1 | D37: 4 | E37: Plex | F37: 6.4 | G37: en | H37: When the ongoing rivalry between farmers Michael and Jack suddenly escalates, it triggers a chain of events that take increasingly violent and devastating turns, leaving both families permanently altered.
A38: The Ballad of Wallis Island | D38: 4 | E38: Prime | F38: 7.4 | G38: en | H38: An eccentric lottery winner who lives alone on a remote island tries to make his fantasies come true by getting his favourite musicians to perform at his home.
A39: Extremely Unique Dynamic | D39: 4 | E39: 12.99 | F39: 7.2 | G39: en | H39: Ryan and Daniel, two childhood best friends and aspiring actors, spend one final weekend together before RYAN has to move to Canada with his fiancé. Wanting to create one lasting memory, they decide to make a movie... about two guys making a movie.. about two guys making a movie. Along the way, they unpack their decades-long friendship and prepare for the next chapters of their respective lives.
A40: Splitsville | D40: 4 | E40: 9.99 | F40: 6.5 | G40: en | H40: After Ashley asks for a divorce, good-natured Carey runs to his friends, Julie and Paul, for support. He’s shocked to discover that the secret to their happiness is an open marriage, that is until Carey crosses the line and throws all of their relationships into chaos.
...

Sheet 2025 Awards
A1: A Big Bold Beautiful Journey | D1: Fantastic Four: First Steps, The | G1: One Battle After Another
A2: 6 | B2: 37 | C2: 58 | D2: 6.8 | E2: 86 | F2: 90 | G2: 7.7 | H2: 94 | I2: 85
A3: A House of Dynamite | D3: Frankenstein | G3: Phoenician Scheme, The
A4: 6.4 | B4: 75 | C4: 78 | D4: 7.4 | E4: 85 | F4: 94 | G4: 6.6 | H4: 77 | I4: 70
A5: A Working Man | D5: Friendship | G5: Psycho Therapy
A6: 5.7 | B6: 47 | C6: 87 | D6: 6.6 | E6: 88 | F6: 73 | G6: 6.2 | H6: 84 | I6: 58
A7: All of You | D7: Good Fortune | G7: Roofman
A8: 6.3 | B8: 72 | C8: 65 | D8: 6.5 | E8: 78 | F8: 81 | G8: 7 | H8: 87 | I8: 85
A9: Amateur, The | D9: Hamnet | G9: Running Man, The
A10: 6.5 | B10: 61 | C10: 87 | D10: 7.9 | E10: 87 | F10: 93 | G10: 6.4 | H10: 62 | I10: 78
A11: Anaconda | D11: Honey Don't! | G11: Secret Agent, The
A12: 5.6 | B12: 48 | C12: 75 | D12: 5.2 | E12: 45 | F12: 39 | G12: 7.3 | H12: 98 | I12: 82
A13: Another Simple Favor | D13: Housemaid, The | G13: Shark Whisperer
A14: 5.3 | B14: 58 | C14: 35 | D14: 6.8 | E14: 73 | F14: 92 | G14: 6.9 | I14: 78
A15: Avatar: Fire and Ash | D15: How to Train Your Dragon | G15: She Rides Shotgun
A16: 7.4 | B16: 66 | C16: 90 | D16: 7.7 | E16: 77 | F16: 97 | G16: 6.5 | H16: 88 | I16: 92
A17: Back in Action | D17: I Know What You Did Last Summer | G17: Sinners
A18: 5.9 | B18: 31 | C18: 60 | D18: 5.1 | E18: 46 | F18: 67 | G18: 7.5 | H18: 97 | I18: 96
A19: Bad Guys 2, The | D19: Is This Thing On? | G19: Sketch
A20: 7 | B20: 87 | C20: 94 | D20: 6.8 | E20: 87 | F20: 83 | G20: 6.6 | H20: 95 | I20: 83
A21: From the World of John Wick: Ballerina | D21: Jurassic World: Rebirth | G21: Snow White
A22: 6.8 | B22: 75 | C22: 92 | D22: 5.8 | E22: 50 | F22: 70 | G22: 2.2 | H22: 39 | I22: 69
A23: Baltimorons, The | D23: KPop Demon Hunters | G23: Sorry, Baby
A24: 6.9 | B24: 93 | C24: 84 | D24: 7.4 | E24: 91 | F24: 99 | G24: 7.1 | H24: 97 | I24: 85
A25: Black Bag | D25: Lilo & Stitch | G25: Springsteen: Deliver Me From Nowhere
A26: 6.7 | B26: 96 | C26: 70 | D26: 6.7 | E26: 72 | F26: 91 | G26: 6.6 | H26: 61 | I26: 82
A27: Bugonia | D27: Long Walk, The | G27: Superman
A28: 7.4 | B28: 87 | C28: 84 | D28: 6.7 | E28: 88 | F28: 85 | G28: 7 | H28: 83 | I28: 90
A29: Captain America: Brave New World | D29: Lost Bus, The | G29: Surfer, The
A30: 5.6 | B30: 46 | C30: 75 | D30: 6.8 | E30: 88 | F30: 95 | G30: 5.9 | H30: 84 | I30: 46
A31: Caught Stealing | D31: Love Hurts | G31: Thunderbolts*
A32: 6.9 | B32: 85 | C32: 83 | D32: 5.3 | E32: 18 | F32: 60 | G32: 7.1 | H32: 88 | I32: 93
A33: Code 3 | D33: Marty Supreme | G33: Thursday Murder Club, The
A34: 7.2 | B34: 78 | C34: 96 | D34: 7.8 | E34: 93 | F34: 82 | G34: 6.5 | H34: 77 | I34: 54
A35: Companion | D35: Mickey 17 | G35: Train Dreams
A36: 6.9 | B36: 93 | C36: 88 | D36: 6.7 | E36: 78 | F36: 73 | G36: 7.5 | H36: 94 | I36: 92
A37: Dangerous Animals | D37: Monkey, The | G37: Wake Up Dead Man: A Knives Out Mystery
A38: 6.4 | B38: 87 | C38: 74 | D38: 5.9 | E38: 77 | F38: 55 | G38: 7.3 | H38: 92 | I38: 94
A39: Day The Earth Blew Up: A Looney Tunes Movie, The | D39: Mountainhead | G39: Warfare
A40: 6.8 | B40: 86 | C40: 88 | D40: 5.4 | E40: 73 | F40: 27 | G40: 7.1 | H40: 92 | I40: 93
...

Sheet 2024
B1: Seen | C1: Own | D1: Want to see | E1: Where | F1: IMDb | G1: =SUM(B:B) -> 69 | H1: =_xlfn.CONCAT(SUM(C:C)," (",SUMPRODUCT(C:C,--(NOT(B:B=1))),")") -> 23 (15) | J1: 45657
A2: Dune: Part Two | B2: 1 | F2: 8.5 | G2: Science-Fiction, Drama, Action Adventure
A3: The Wild Robot | B3: 1 | F3: 8.2 | G3: Animation, Science-Fiction, Family Animation
A4: The Brutalist | B4: 1 | F4: 8.1 | G4: Drama
A5: Wicked: Part One | B5: 1 | F5: 8 | G5: Fantasy, Drama, Romance
A6: Anora | B6: 1 | F6: 7.9 | G6: Comedy, Drama, Romance, Emotional Drama, Dramedy
A7: Flow | B7: 1 | F7: 7.9 | G7: Animation, Fantasy, Action & Adventure, Kids & Family, Family Animation
A8: A Complete Unknown | B8: 1 | F8: 7.8 | G8: Drama, Music & Musical, History, Music Biopics
A9: Memoir of a Snail | B9: 1 | F9: 7.8 | G9: Animation, Drama, Claymation
A10: Nosferatu | B10: 1 | C10: 1 | F10: 7.8 | G10: Fantasy, Horror, Dark Fantasy
A11: Pixar's Inside Out 2 | B11: 1 | F11: 7.6 | G11: Animation, Action & Adventure, Comedy, Kids & Family, Drama, Fantasy, Family Animation
A12: Deadpool & Wolverine | B12: 1 | F12: 7.6 | G12: Action & Adventure, Comedy, Science-Fiction, Superhero
A13: A Real Pain | B13: 1 | F13: 7.6 | G13: Drama, Comedy, Dramedy
A14: Will & Harper | B14: 1 | F14: 7.5 | G14: Comedy, Documentary
A15: Nickel Boys | B15: 1 | F15: 7.5 | G15: Drama, Emotional Drama
A16: The Substance | B16: 1 | C16: 1 | F16: 7.4 | G16: Science-Fiction, Horror, Drama
A17: Conclave | B17: 1 | F17: 7.4 | G17: Drama, Mystery Thriller
A18: September 5 | B18: 1 | C18: 1 | F18: 7.1 | G18: Drama, History, Mystery & Thriller, Emotional Drama
A19: The Apprentice | B19: 1 | C19: 1 | F19: 7.1 | G19: History, Drama, Biopics
A20: Challengers | B20: 1 | F20: 7.1 | G20: Drama, Comedy, Romance, Sport, Sports Drama
A21: Saturday Night | B21: 1 | F21: 7.1 | G21: Drama, History, Comedy, Dramedy
A22: Thelma | B22: 1 | F22: 7 | G22: Comedy, Action & Adventure, Action Comedy
A23: Juror #2 | B23: 1 | F23: 7 | G23: Crime, Drama, Mystery Thriller
A24: Wicked Little Letters | B24: 1 | F24: 7 | G24: Comedy, Crime, Drama, History, Mystery & Thriller, Dramedy
A25: Civil War | B25: 1 | F25: 7 | G25: Action & Adventure, Mystery & Thriller, Drama, War Epics
A26: We Live in Time | B26: 1 | F26: 7 | G26: Drama, Romance, Romantic Drama
A27: Moana 2 | B27: 1 | F27: 7 | G27: Action & Adventure, Kids & Family, Comedy, Animation, Fantasy, Family Animation
A28: A Different Man | B28: 1 | F28: 7 | G28: Drama, Comedy, Mystery Thriller
A29: The Fall Guy | B29: 1 | F29: 6.9 | G29: Comedy, Drama, Romance, Action & Adventure, Action Comedy
A30: My Old Ass | B30: 1 | F30: 6.9 | G30: Romance, Comedy, Drama, Dramedy
A31: Monkey Man | B31: 1 | C31: 1 | F31: 6.8 | G31: Action & Adventure, Mystery & Thriller, Crime, Action Thriller
A32: The Ministry of Ungentlemanly Warfare | B32: 1 | F32: 6.8 | G32: Action & Adventure, Comedy, War & Military, War Drama
A33: Hit Man | B33: 1 | F33: 6.8 | G33: Comedy, Crime, Romance, Action Comedy
A34: Emilia Perez | B34: 1 | F34: 6.8 | G34: Drama, Mystery & Thriller, Comedy, Crime, Dark Crime
A35: That Christmas | B35: 1 | F35: 6.8 | G35: Action & Adventure, Animation, Comedy, Kids & Family, Fantasy, Holiday, Family Animation
A36: Mufasa: The Lion King | B36: 1 | F36: 6.8 | G36: Drama, Kids & Family, Fantasy, Animation, Music & Musical, Action & Adventure, Family Animation
A37: The Bikeriders | B37: 1 | C37: 1 | F37: 6.7 | G37: Crime, Drama, Organized Crime
A38: Beetlejuice Beetlejuice | B38: 1 | F38: 6.7 | G38: Horror, Comedy, Fantasy, Horror Comedy
A39: Gladiator II | B39: 1 | F39: 6.7 | G39: Drama, Action Adventure
A40: It's What's Inside | B40: 1 | F40: 6.6 | G40: Science-Fiction, Comedy, Mystery & Thriller, SciFi Horror
...

Sheet 2024 Awards
A1: A Complete Unknown | D1: Dune: Part Two | G1: Nickel Boys
A2: 7.5 | B2: 81 | C2: 95 | D2: 8.5 | E2: 92 | F2: 95 | G2: 7.5 | H2: 91 | I2: 75
A3: A Different Man | D3: Emilia Perez | G3: Nightbitch
A4: 6.9 | B4: 93 | C4: 89 | D4: 5.4 | E4: 72 | F4: 16 | G4: 5.6 | H4: 59 | I4: 47
A5: A Family Affair | D5: Fall Guy, The | G5: Pixar's Inside Out 2
A6: 5.3 | B6: 35 | C6: 30 | D6: 6.8 | E6: 82 | F6: 85 | G6: 7.5 | H6: 91 | I6: 95
A7: A Quiet Place: Day One | D7: Flow | G7: Red One
A8: 6.3 | B8: 86 | C8: 72 | D8: 7.9 | E8: 97 | F8: 98 | G8: 6.3 | H8: 30 | I8: 90
A9: A Real Pain | D9: Fly Me to the Moon | G9: Saturday Night
A10: 7.1 | B10: 96 | C10: 81 | D10: 6.6 | E10: 65 | F10: 89 | G10: 6.9 | H10: 78 | I10: 84
A11: Anora | D11: Garfield Movie, The | G11: September 5
A12: 7.7 | B12: 93 | C12: 89 | D12: 5.7 | E12: 37 | F12: 79 | G12: 7.1 | H12: 93 | I12: 90
A13: Apprentice, The | D13: Ghostbusters: Frozen Empire | G13: Sleeping Dogs
A14: 7.1 | B14: 83 | C14: 84 | D14: 6.1 | E14: 42 | F14: 82 | G14: 6.2 | H14: 42 | I14: 82
A15: Argylle | D15: Gladiator II | G15: Substance, The
A16: 5.6 | B16: 33 | C16: 70 | D16: 6.6 | E16: 71 | F16: 82 | G16: 7.3 | H16: 90 | I16: 75
A17: Babes | D17: Godzilla x Kong: The New Empire | G17: That Christmas
A18: 6.3 | B18: 88 | C18: 78 | D18: 6.1 | E18: 54 | F18: 90 | G18: 6.8 | H18: 67 | I18: 74
A19: Beetlejuice Beetlejuice | D19: Greedy People | G19: Thelma
A20: 6.7 | B20: 75 | C20: 79 | D20: 6.2 | E20: 60 | F20: 57 | G20: 7 | H20: 98 | I20: 83
A21: Bikeriders, The | D21: Here | G21: Trap
A22: 6.6 | B22: 80 | C22: 74 | D22: 6.3 | E22: 37 | F22: 53 | G22: 5.8 | H22: 57 | I22: 65
A23: Blink Twice | D23: Hit Man | G23: Twisters
A24: 6.5 | B24: 75 | C24: 71 | D24: 6.8 | E24: 95 | F24: 91 | G24: 6.5 | H24: 75 | I24: 90
A25: Bob Marley: One Love | D25: IF - Imaginary Friend | G25: Unfrosted
A26: 6.2 | B26: 43 | C26: 91 | D26: 6.4 | E26: 50 | F26: 86 | G26: 5.5 | H26: 40 | I26: 50
A27: Boy Kills World | D27: It's What's Inside | G27: Venom: The Last Dance
A28: 6.4 | B28: 58 | C28: 73 | D28: 6.6 | E28: 79 | F28: 69 | G28: 6 | H28: 40 | I28: 80
A29: Brutalist, The | D29: Joker: Folie à Deux | G29: Watchers, The
A30: 7.6 | B30: 94 | C30: 80 | D30: 5.2 | E30: 31 | F30: 31 | G30: 5.7 | H30: 33 | I30: 50
A31: Carry-On | D31: Juror #2 | G31: We Live in Time
A32: 6.5 | B32: 87 | C32: 51 | D32: 7 | E32: 93 | F32: 91 | G32: 7 | H32: 79 | I32: 83
A33: Challengers | D33: Kraven the Hunter | G33: Wicked Little Letters
A34: 7.1 | B34: 88 | C34: 75 | D34: 5.4 | E34: 16 | F34: 73 | G34: 7 | H34: 80 | I34: 92
A35: Civil War | D35: Memoir of a Snail | G35: Wicked: Part One
A36: 7 | B36: 81 | C36: 69 | D36: 7.8 | E36: 95 | F36: 82 | G36: 7.6 | H36: 88 | I36: 95
A37: Conclave | D37: Ministry of Ungentlemanly Warfare, The | G37: Wild Robot, The
A38: 7.4 | B38: 93 | C38: 86 | D38: 6.8 | E38: 68 | F38: 92 | G38: 8.2 | H38: 96 | I38: 98
A39: Deadpool & Wolverine | D39: Moana 2 | G39: Will & Harper
A40: 7.6 | B40: 78 | C40: 94 | D40: 6.8 | E40: 61 | F40: 86 | G40: 7.4 | H40: 99 | I40: 81
...

Sheet 2023
B1: Seen | C1: Own | D1: Want to see | E1: Where | F1: IMDb | G1: =SUM(B:B) -> 59 | H1: =_xlfn.CONCAT(SUM(C:C)," (",SUMPRODUCT(C:C,--(NOT(B:B=1))),")") -> 22 (13)
A2: No Hard Feelings | B2: 1 | C2: 1 | E2: Netflix | F2: 6.4 | G2: Comedy, Romance | H2: Maddie is working as an Uber driver in Montauk, New York. She’s already struggling to make ends meet but when her car gets repossessed she looks set to face bankruptcy if she can’t find a solution. Desperate for something, she accepts an unusual posting on Craigslist that would win her a Buick Regal. In exchange for the car, she needs to date Percy, the introverted son of the helicopter parents behind the ad. Hoping to bring him out of his social seclusion, the parents agree that Maddie will seduce him and become Percy’s girlfriend in order to teach him about adult life. But unleashing the full force of Percy’s pent-up adolescence has consequences no one could imagine.
A3: Barbie | B3: 1 | C3: 1 | E3: Plex | F3: 7 | G3: Action & Adventure, Fantasy, Comedy | H3: When Barbie leaves Barbieland and finds herself in the real world, she's a fish out of water longing for her old life. Meanwhile, her boyfriend Ken seems at ease with the impossible standards of the human world. Can their relationship survive this clash of ideals?
A4: Asteroid City | B4: 1 | C4: 1 | E4: Plex | F4: 6.6 | G4: Comedy, Drama, Romance, Science-Fiction | H4: Asteroid City is the science-loving American’s top holiday destination. This small desert town plays host to the 1955 Junior Stargazer and Space Cadet conventions. In the dusty desert heat, sudden spectacular events interrupt the program and put Asteroid City on the map.
A5: Cocaine Bear | B5: 1 | C5: 1 | E5: Plex | F5: 5.9 | G5: Mystery & Thriller, Comedy, Crime | H5: Cocaine Bear is the story of just that: a black bear who somehow gets his hands on a massive amount of cocaine and swallows it. The result is a drug-fueled rampage of mayhem and murder.
A6: Oppenheimer | B6: 1 | C6: 1 | F6: 8.4 | G6: Drama, History | H6: The film tells the tale of J. Robert Oppenheimer, a theoretical physicist. Oppenheimer was a leading figure of the Manhattan Project – a codename for the effort to develop weapons strong enough to lead the Allied Forces to victory and tightly secure the United States role as a world’s super power. The events of the film take place during the Second World War while Oppenheimer worked for the Los Alamos Laboratory where the bombs were created.
A7: John Wick: Chapter 4 | B7: 1 | C7: 1 | F7: 7.7 | G7: Action & Adventure, Mystery & Thriller, Crime | H7: Before he can earn his freedom, Wick must face off against a new enemy with powerful alliances across the globe and forces that turn old friends into foes.
A8: Disney's Wish | B8: 1 | C8: 1 | F8: 5.8 | G8: Action & Adventure, Animation, Kids & Family, Fantasy, Comedy | H8: Asha is a teenager living in the Kingdom of Rosas. She senses uncommon darkness in the ruler King Magnifico. She pleads to the night sky for help in understanding and is shocked when it answers. A star called Star falls from above and answers her wish. Together Asha and Star must find a way to battle the oncoming darkness and save the people of Rosas.
A9: Tetris | B9: 1 | E9: Apple | F9: 7.4 | G9: Drama, History, Mystery & Thriller | H9: Henk Rogers is a video games publisher who has found the perfect game – Tetris. The only problem is, that it is designed and created by Alexey Pajitnov, a Russian computer engineer. In the midst of the Cold War, the pair seek to bring the game to an international audience and risk diplomatic and commercial disaster in the process. The legal battle winds up involving Hiroshi Yamauchi, president of Nintendo, British media mogul, Robert Maxwell, countless KGB agents, and even Mikhail Gorbachev himself. This high-stakes thriller is the story of one man’s mission to bring the most addictive video game to millions of households around the world.
A10: Guardians of the Galaxy Vol. 3 | B10: 1 | E10: Disney | F10: 7.9 | G10: Action & Adventure, Comedy, Science-Fiction | H10: As Rocket's past comes back to haunt him, he finds himself in mortal danger. In order to save his life, the Guardians must band together and leave the comfort of their new home on Knowhere. With new villains always on the horizon and long-expected Marvel favourite Adam Warlock making his debut in the Marvel Cinematic Universe (MCU), the Guardians of the Galaxy have their work cut out for them in this third instalment.
A11: The Little Mermaid | B11: 1 | E11: Disney | F11: 7.2 | G11: Action & Adventure, Kids & Family, Fantasy, Romance | H11: Ariel is the daughter of King Triton, a proud ruler of the underwater Atlantica kingdom. Wary and prejudiced against the humans above the surface, King Triton doesn’t understand his daughters deep fascination with the human world. The young princess is cunning and rebellious. She is not content to stay in Atlantica and wants to experience the human world. Her curiosity however plays into the hands of the sly and seditious sea-witch Ursula, who plots to take over Atlantica herself. When Ariel saves the life of Prince Eric, a human man drowning in the sea, the two fall in love and the stage is set. Ursula offers Ariel a trade: she will make the princess human in exchange for her beautiful singing voice.
A12: Pixar's Elemental | B12: 1 | E12: Disney | F12: 7 | G12: Comedy, Kids & Family, Fantasy, Romance, Animation, Drama, Science-Fiction | H12: This touching tale is set in a city where the residents personify each of the elements; water, fire, air, and land. Ember is a passionate and fiery go-getter while Wade likes to take things as they come and go with the flow. Some elements mix better than others and as they face their differences they begin to see just how much they have in common.
A13: Ant-Man and the Wasp: Quantumania | B13: 1 | E13: Disney | F13: 6.1 | G13: Science-Fiction, Action & Adventure, Comedy | H13: After battling through the quantum realm in their last outing together, Ant-Man and the Wasp: Quantumania sees the duo return for their third instalment to face down a new challenge. Scott Lang and Hope Pym are reunited to tackle their most difficult adversary yet, the time-travelling, multiverse villain, Kang the Conqueror.
A14: Disney's Haunted Mansion | B14: 1 | E14: Disney | F14: 6.1 | G14: Comedy, Horror, Kids & Family, Fantasy, Drama | H14: Gabbie has found the perfect home for her and her son, which promises a new beginning for them in New Orleans. But the new move isn’t a smooth one. There are strange and inexplicable things starting to happen. Could the house be haunted with dark spirits? To find out and hopefully rid herself of the supernatural beings, she enlists the help of several people, including a priest, a psychic, a historian, and a paranormal expert.
A15: Quiz Lady | B15: 1 | E15: Hulu | F15: 6.7 | G15: Comedy | H15: A brilliant but tightly wound, gameshow-obsessed young woman, Anne, and her estranged, train-wreck of a sister Jenny, must work together to help cover their mother’s gambling debts. When Anne’s beloved dog is kidnapped, they set out on a wild, cross-country trek to get the cash the only way they know how: by turning Anne into a bona-fide gameshow champion.
A16: To Catch a Killer | B16: 1 | E16: Hulu | F16: 6.6 | G16: Mystery & Thriller, Crime, Drama, Action & Adventure | H16: Baltimore. New Year's Eve. A talented but troubled police officer is recruited by the FBI's chief investigator to help profile and track down a mass murderer.
A17: A Haunting in Venice | B17: 1 | E17: Hulu | F17: 6.5 | G17: Mystery & Thriller, Crime, Drama, Horror | H17: Hercule Poirot is trying to enjoy a quiet retirement in Venice when he is invited to a seance at a haunted palazzo. As things take a turn for the supernatural, the mustachioed detective must use his powers of observation to discover the true intentions of the group, who are gathered to connect to the dead. A murder, a disappearance, and a history of strange happenings in the area all connect in one of Poirot’s scariest cases yet.
A18: The Flash | B18: 1 | E18: Max | F18: 6.7 | G18: Science-Fiction, Action & Adventure, Fantasy | H18: The speedster decides to use his superhuman pace to travel back in time and prevent his mother from dying. But his move has unexpected and chaotic consequences. The Flash finds himself stuck in a reality where the evil General Zod has re-emerged and no superheroes exist to challenge him. The Flash must rally with what allies he can find. Between a retired Batman, another Barry Allen, and a locked-up Supergirl, The Flash has friends, but does he have the time to save this world from certain destruction?
A19: Blue Beetle | B19: 1 | E19: Max | F19: 6 | G19: Action & Adventure, Science-Fiction, Mystery & Thriller | H19: Jaime Reyes is a freshly graduated college student returning home to a new life. Facing new challenges and struggles, Jaime must find his purpose and position in society. What he doesn't know is that destiny has a plan for him. When a mysterious ancient scarab attaches to his spine, it gives him the ability to travel through space in blue alien armor. Suddenly the host of this symbiotic power, Jaime becomes a superhero protected and powered by this alien technology.
A20: Meg 2: The Trench | B20: 1 | E20: Max | F20: 5 | G20: Action & Adventure, Science-Fiction, Horror, Mystery & Thriller | H20: No place on Earth is deeper than the Mariana Trench and at that depth, in the darkest most uninhabitable place on the planet, something is lurking. Jonas Taylor is back and facing a larger more terrifying shark than ever before. The ex-rescue diver has already faced down a prehistoric Megalodon and at great personal cost. Now the ancient beast returns, stronger, smarter, and more daring than ever. With a new crew assembled, featuring some familiar faces, Taylor will struggle to save them all from the jaws of the giant shark set upon destruction and mayhem.
... A40: Candy Cane Lane | B40: 1 | E40: Prime | F40: 5.6 | G40: Comedy, Fantasy, Kids & Family | H40: A man, determined to win the neighborhood's annual Christmas decorating contest, makes a pact with an elf to help him win. However, the elf casts a spell bringing the twelve days of Christmas to life, bringing chaos to the small, unsuspecting town.
A41: Poor Things | B41: 1 | F41: 8.5 | G41: Science-Fiction, Comedy, Fantasy, Drama, Romance | H41: Having already died and been brought back to life by an eccentric scientist, Bella is a truly unusual woman. Living under the guardianship of her creator, Dr. Godwin Baxter, Bella is hungry to learn about the world around her. When she meets a charming but ultimately flawed lawyer, she escapes his care to travel around the globe. Undefined by ideas of what a woman should be, Bella is free to challenge the social norms of the day and live her life as a liberated being.
A42: Past Lives | B42: 1 | F42: 8 | G42: Romance, Drama | H42: Nora and Hae Sung were deeply connected childhood friends torn apart when Nora and her family emigrated from South Korea. 20 years on, Nora is living in the United States and is married to Arthur, a white American. When Nora learns that Hae Sung has been searching for her, the two rekindle their connection. As they meet each other again the pair struggle to draw the line between who they are and who they could have been.
A43: The Holdovers | B43: 1 | C43: 1 | F43: 8 | G43: Comedy, Drama | H43: Nobody at Barton Academy likes Paul Hunham – a history teacher who is tired of the world and everyone in it. But when he’s put in charge of students who have nowhere to go over Christmas, Paul faces a new and unprecedented challenge – how to care for students who are living without a happy home to return to. Angus is one of those. Grieving the loss of his father, Angus is a holdover at Barton Academy and is being taken care of by Paul. The pair must learn how to understand each other if they are to survive the Holiday period.
A44: Killers of the Flower Moon | B44: 1 | F44: 7.9 | G44: Drama, Western, Crime, History, Romance | H44: A murder mystery surrounding members of the Osage tribe unfolds in 1920s America. The Native-American tribe, who reside in Oklahoma, were targeted after oil was discovered on their ancestral land. The case marks one of the first major investigations by the new Federal Bureau of Investigation (FBI) and shines a light on the notorious J. Edgar Hoover.
A45: Saltburn | B45: 1 | F45: 7.5 | G45: Comedy, Drama, Mystery & Thriller | H45: Oliver Quick is struggling to find his place in the aristocratic world of Oxford University. As he wrestles with his desire to fit in, he finds himself drawn to Felix Catton, a wealthy student from a prestigious family. When Oliver is invited to Saltburn, the family’s expansive estate, he gets mixed up in the strange and alluring world of the wealthy.
A46: The Hunger Games: The Ballad of Songbirds & Snakes | B46: 1 | F46: 7.1 | G46: Science-Fiction, Mystery & Thriller, War & Military, Action & Adventure, Drama, Romance | H46: Coriolanus Snow was not always the tyrannical and ruthless president he would become. Born into a family of high-status but decreasing wealth, Snow must use his charisma and intelligence to forge a path. A top student at the Academy in Panem, Snow became the mentor for District 12’s tribute Lucy Gray Baird and ot would not be the last time a tribute from District 12 would have a huge impact on the life of Coriolanus Snow. Set before the time of Katniss Everdeen and the resulting Hunger Games stories, The Ballad of Songbirds & Snakes tells the story of a young Snow training Lucy Gray to be victorious in the Hunger Games and as their relationship develops so too does his thirst for control and power, charting his rise to the top.
A47: Dumb Money | B47: 1 | F47: 6.9 | G47: Comedy, Drama, History | H47: A group of rogue investors who discuss their trades on the Reddit page, Wall Street Bets become the center of a huge controversy. The unlikely rabble manages a shocking short squeeze on two major hedge funds by betting on the fate of consumer electronics brand GameStop.
A48: The Creator | B48: 1 | F48: 6.9 | G48: Action & Adventure, Drama, Science-Fiction, Mystery & Thriller | H48: In a conflict between human beings and the mechanized battalions of artificial intelligence, Joshua is on a secret mission. The former special agent is on a covert mission to kill the Creator, the one who designed and built the advanced AI seeking to end human existence. Grieving for his lost wife, Joshua is searching for a new weapon that has been developed to end the war once and for all. But once he finds it, things become more complicated than they first seemed.
A49: Napoleon | B49: 1 | F49: 6.6 | G49: Drama, History, War & Military, Action & Adventure | H49: Napoleon Bonaparte came from nothing and rose through the ranks of the military to become the Emperor of France. Conquering all in his wake, the brilliant military strategist won battle after battle with his pure lust for power. But at the heart of his relentless conquest was his tempestuous relationship with the Empress Josephine. Their volatile love reveals a man ruled by his passions and whims leading eventually to his downfall.
A50: Plane | B50: 1 | F50: 6.5 | G50: Action & Adventure, Mystery & Thriller | H50: After a heroic job of successfully landing his storm-damaged aircraft in a war zone, a fearless pilot finds himself between the agendas of multiple militias planning to take the plane and its passengers hostage.
A51: The Marvels | B51: 1 | F51: 5.9 | G51: Science-Fiction, Action & Adventure, Fantas | H51: Carol Danvers has been busy battling galactic threats off-world as Captain Marvel. While investigating a wormhole in outer space, she becomes inextricably linked to her niece (Monica Rambeau) and her biggest superfan (Kamala Khan). While Captain Marvel usually flies solo, this cosmic coincidence forces her to work with others to save the universe from the threat of the Kree.
A52: Freelance | B52: 1 | F52: 5.4 | G52: Comedy, Action & Adventure | H52: An ex-special forces operative takes a job to provide security for a journalist as she interviews a dictator, but when a military coup breaks out in the middle of the interview, they are forced to escape into the jungle.
A53: American Fiction | B53: 1
A54: Wonka | B54: 1
A55: Anyone But You | B55: 1
A56: Aquaman and the Lost Kingdom | B56: 1
A57: Migration | B57: 1
A58: The Iron Claw | B58: 1 | C58: 1
A59: The Boys in the Boat | B59: 1
...

Sheet 2022
B1: Seen | C1: Own | D1: Want to see | E1: Where | F1: IMDb | G1: =SUM(B:B) -> 74 | H1: =_xlfn.CONCAT(SUM(C:C)," (",SUMPRODUCT(C:C,--(NOT(B:B=1))),")") -> 48 (21)
A2: Jackass Forever | B2: 1 | C2: 1
A3: The Batman | B3: 1 | C3: 1
A4: Everything Everywhere All at Once | B4: 1 | C4: 1
A5: Fantastic Beasts: The Secrets of Dumbledore | B5: 1 | C5: 1
A6: The Bad Guys | B6: 1 | C6: 1
A7: The Northman | B7: 1 | C7: 1
A8: The Unbearable Weight of Massive Talent | B8: 1 | C8: 1
A9: The Bob's Burgers Movie | B9: 1 | C9: 1
A10: Top Gun: Maverick | B10: 1 | C10: 1
A11: Where the Crawdads Sing | B11: 1 | C11: 1
A12: Nope | B12: 1 | C12: 1
A13: DC League of Super-Pets | B13: 1 | C13: 1
... A28: Marcel the Shell with Shoes On | B28: 1 | C28: 1
A29: The 355 | B29: 1
A30: Moonfall | B30: 1
A31: Death on the Nile | B31: 1
A32: Marry Me | B32: 1
A33: Dog | B33: 1
A34: Uncharted | B34: 1
A35: Studio 666 | B35: 1
A36: The Adam Project | B36: 1
A37: The Outfit | B37: 1
A38: The Lost City | B38: 1
A39: Morbius | B39: 1
A40: Doctor Strange in the Multiverse of Madness | B40: 1
... A75: Ambulance | B75: 1
A76: Cyrano | C76: 1
A77: After Yang | C77: 1
A78: Sonic the Hedgehog 2 | C78: 1
A79: Fall | C79: 1
A80: Emily the Criminal | C80: 1
A81: Three Thousand Years of Longing | C81: 1
A82: Confess, Fletch | C82: 1
A83: Meet Cute | C83: 1
A84: The Good House | C84: 1
A85: Armageddon Time | C85: 1
A86: Poker Face | C86: 1
A87: Spoiler Alert | C87: 1
... A96: Smile | C96: 1
...

Sheet 2021
B1: Seen | C1: Own | D1: Want to see | E1: Where | F1: IMDb | G1: =SUM(B:B) -> 69 | H1: =_xlfn.CONCAT(SUM(C:C)," (",SUMPRODUCT(C:C,--(NOT(B:B=1))),")") -> 49 (15)
A2: Barb and Star Go to Vista Del Mar | B2: 1 | C2: 1
A3: Judas and the Black Messiah | B3: 1 | C3: 1
A4: Tom & Jerry | B4: 1 | C4: 1
A5: The Father | B5: 1 | C5: 1
A6: Zack Snyder's Justice League | B6: 1 | C6: 1
A7: The Courier | B7: 1 | C7: 1
A8: Nobody | B8: 1 | C8: 1
A9: Marvel's Black Widow | B9: 1 | C9: 1
A10: The Suicide Squad | B10: 1 | C10: 1
A11: Free Guy | B11: 1 | C11: 1
A12: Respect | B12: 1 | C12: 1
A13: The Protégé | B13: 1 | C13: 1
... A35: Spencer | B35: 1 | C35: 1
A36: The Dig | B36: 1
A37: Nomadland | B37: 1
A38: The United States vs. Billie Holiday | B38: 1
A39: Raya and the Last Dragon | B39: 1
A40: Godzilla vs. Kong | B40: 1
A41: The Woman in the Window | B41: 1
A42: Army of the Dead | B42: 1
A43: Cruella | B43: 1
A44: In the Heights | B44: 1
A45: Pixar's Luca | B45: 1
A46: No Sudden Move | B46: 1
A47: Space Jam: A New Legacy | B47: 1
... A70: The King's Man | B70: 1
A71: Boogie | C71: 1
A72: Pixie | C72: 1
A73: Together Together | C73: 1
A74: The Mitchells vs. the Machines | C74: 1
A75: Stillwater | C75: 1
A76: Malignant | C76: 1
A77: The Card Counter | C77: 1
A78: No Time To Die | C78: 1
A79: C'mon C'mon | C79: 1
A80: The Beatles: Get Back | C80: 1
A81: The Matrix Resurrections | C81: 1
A82: Last Looks | C82: 1
... A85: Don't Breathe 2 | C85: 1
...

Sheet 2020
B1: Seen | C1: Own | D1: Want to see | E1: Where | F1: IMDb | G1: =SUM(B:B) -> 54 | H1: =_xlfn.CONCAT(SUM(C:C)," (",SUMPRODUCT(C:C,--(NOT(B:B=1))),")") -> 30 (11)
A2: Dolittle | B2: 1 | C2: 1
A3: The Gentlemen | B3: 1 | C3: 1
A4: Birds of Prey: And the Fantabulous Emancipation of One Harley Quinn | B4: 1 | C4: 1
A5: Sonic the Hedgehog | B5: 1 | C5: 1
A6: The Invisible Man | B6: 1 | C6: 1
A7: The Way Back | B7: 1 | C7: 1
A8: The Hunt | B8: 1 | C8: 1
A9: Scoob! | B9: 1 | C9: 1
A10: The King of Staten Island | B10: 1 | C10: 1
A11: Irresistible | B11: 1 | C11: 1
A12: Tenet | B12: 1 | C12: 1
A13: Antebellum | B13: 1 | C13: 1
... A20: Class Action Park | B20: 1 | C20: 1
A21: Like a Boss | B21: 1
A22: Horse Girl | B22: 1
A23: The Photograph | B23: 1
A24: Downhill | B24: 1
A25: Emma | B25: 1
A26: Pixar's Onward | B26: 1
A27: The Banker | B27: 1
A28: Lost Girls | B28: 1
A29: The Lovebirds | B29: 1
A30: The Vast of Night | B30: 1
A31: Shirley | B31: 1
A32: Da 5 Bloods | B32: 1
... A55: Songbird | B55: 1
A56: Bad Boys For Life | C56: 1
A57: The Rhythm Section | C57: 1
A58: The Jesus Rolls | C58: 1
A59: Bill & Ted Face the Music | C59: 1
A60: Mulan | C60: 1
A61: Kajillionaire | C61: 1
A62: Freaky | C62: 1
A63: Half Brothers | C63: 1
A64: Fatale | C64: 1
A65: The Outpost | C65: 1
A66: The Grudge
A67: Underwater
A68: Les Misérables
...

Sheet 2019
B1: Seen | C1: Own | D1: Want to see | E1: Where | F1: IMDb | G1: =SUM(B:B) -> 76 | H1: =_xlfn.CONCAT(SUM(C:C)," (",SUMPRODUCT(C:C,--(NOT(B:B=1))),")") -> 64 (23)
A2: The Man Who Killed Hitler and Then The Bigfoot | B2: 1 | C2: 1
A3: Isn't It Romantic | B3: 1 | C3: 1
A4: Captain Marvel | B4: 1 | C4: 1
A5: Us | B5: 1 | C5: 1
A6: The Beach Bum | B6: 1 | C6: 1
A7: Dumbo | B7: 1 | C7: 1
A8: Shazam! | B8: 1 | C8: 1
A9: Marvel's Avengers: Endgame | B9: 1 | C9: 1
A10: Long Shot | B10: 1 | C10: 1
A11: The Hustle | B11: 1 | C11: 1
A12: John Wick: Chapter 3 - Parabellum | B12: 1 | C12: 1
A13: Booksmart | B13: 1 | C13: 1
... A40: Little Women | B40: 1 | C40: 1
A41: 1917 | B41: 1 | C41: 1
A42: Parasite | B42: 1 | C42: 1
A43: A Dog's Way Home | B43: 1
A44: Captive State | B44: 1
A45: The Highwaymen | B45: 1
A46: Extremely Wicked, Shockingly Evil, and Vile | B46: 1
A47: A Dog's Journey | B47: 1
A48: Photograph | B48: 1
A49: Aladdin | B49: 1
A50: Godzilla: King of Monsters | B50: 1
A51: The Secret Life of Pets 2 | B51: 1
A52: Late Night | B52: 1
A53: Men in Black: International | B53: 1
A54: The Art of Racing in the Rain | B54: 1
... A77: The Report | B77: 1
A78: The Upside | C78: 1
A79: Glass | C79: 1
A80: Fighting with My Family | C80: 1
A81: Missing Link | C81: 1
A82: Pokémon Detective Pikachu | C82: 1
A83: Brightburn | C83: 1
A84: Shaft | C84: 1
A85: The Dead Don't Die | C85: 1
A86: Anna | C86: 1
A87: Crawl | C87: 1
A88: Judy | C88: 1
...

Sheet 2018
B1: Seen | C1: Own | D1: Want to see | E1: Where | F1: IMDb | G1: =SUM(B:B) -> 64 | H1: =_xlfn.CONCAT(SUM(C:C)," (",SUMPRODUCT(C:C,--(NOT(B:B=1))),")") -> 82 (34)
A2: Winchester | B2: 1 | C2: 1
A3: Widows | B3: 1 | C3: 1
A4: White Boy Rick | B4: 1 | C4: 1
A5: Venom | B5: 1 | C5: 1
A6: The Commuter | B6: 1 | C6: 1
A7: Spider-Man: Into the Spider-Verse | B7: 1 | C7: 1
A8: Smallfoot | B8: 1 | C8: 1
A9: Skyscraper | B9: 1 | C9: 1
A10: Searching | B10: 1 | C10: 1
A11: Red Sparrow | B11: 1 | C11: 1
A12: Rampage | B12: 1 | C12: 1
A13: Ocean's 8 | B13: 1 | C13: 1
... A47: Leave No Trace | B47: 1 | C47: 2
A48: Welcome to Marwen | B48: 1
A49: Vice | B49: 1
A50: The Spy Who Dumped Me | B50: 1
A51: The Meg | B51: 1
A52: The King | B52: 1
A53: The Happytime Murders | B53: 1
A54: The Favourite | B54: 1
A55: The Ballad of Buster Scruggs | B55: 1
A56: Sorry to Bother You | B56: 1
A57: Operation Finale | B57: 1
A58: Love, Simon | B58: 1
A59: Jurassic World: Fallen Kingdom | B59: 1
... A65: Adrift | B65: 1
A66: Christopher Robin | C66: 1
A67: The Wife | C67: 1
A68: The Sisters Brothers | C68: 1
A69: The Mule | C69: 1
A70: The Hate U Give | C70: 1
A71: The Front Runner | C71: 1
A72: The Catcher Was a Spy | C72: 1
A73: The 15:17 to Paris | C73: 1
A74: Terminal | C74: 1
A75: Super Troopers 2 | C75: 1
A76: Sicario: Day of the Soldado | C76: 1
A77: Ready Player One | C77: 1
... A98: Borg vs McEnroe | C98: 1
...

Sheet 2017
B1: Seen | C1: Own | D1: Want to see | E1: Where | F1: IMDb | G1: =SUM(B:B) -> 53 | H1: =_xlfn.CONCAT(SUM(C:C)," (",SUMPRODUCT(C:C,--(NOT(B:B=1))),")") -> 77 (29)
A2: A Dog's Purpose | B2: 1 | C2: 1
A3: John Wick: Chapter Two | B3: 1 | C3: 1
A4: The LEGO Batman Movie | B4: 1 | C4: 1
A5: Get Out | B5: 1 | C5: 1
A6: Kong: Skull Island | B6: 1 | C6: 1
A7: The Boss Baby | B7: 1 | C7: 1
A8: Buster's Mal Heart | B8: 1 | C8: 1
A9: Snatched | B9: 1 | C9: 1
A10: Baywatch | B10: 1 | C10: 1
A11: Pirates of the Caribbean: Dead Men Tell No Tales | B11: 1 | C11: 1
A12: The Mummy | B12: 1 | C12: 1
A13: 47 Meters Down | B13: 1 | C13: 1
... A48: Justice League | B48: 1 | C48: 1
A49: Guardians of the Galaxy Vol. 2 | B49: 1
A50: Kingsman: The Golden Circle | B50: 1
A51: Marshall | B51: 1
A52: The Post | B52: 1
A53: War Machine | B53: 1
A54: Logan | C54: 1
A55: Beauty and the Beast | C55: 1
A56: CHIPS | C56: 1
A57: The Zookeeper's Wife | C57: 1
A58: Going in Style | C58: 1
A59: The Lost City of Z | C59: 1
A60: King Arthur: Legend of the Sword | C60: 1
A61: Alien: Covenant | C61: 1
A62: All Eyez on Me | C62: 1
A63: The Big Sick | C63: 1
A64: Detroit | C64: 1
A65: Blade Runner 2049 | C65: 1
... A78: Brawl in Cell Block 99 | C78: 1
A79: Jungle | B79: 1 | C79: 1
A80: The Founder | C80: 1
A81: Life | C81: 1
A82: The Beguiled | C82: 1
A83: Victoria & Abdul | C83: 1
A84: Split | D84: 1
A85: Rings | D85: 1
A86: The Comedian | D86: 1
...

Sheet 2016
B1: Seen | C1: Own | D1: Want to see | E1: Where | F1: IMDb | G1: =SUM(B:B) -> 35 | H1: =_xlfn.CONCAT(SUM(C:C)," (",SUMPRODUCT(C:C,--(NOT(B:B=1))),")") -> 65 (30)
A2: Deadpool | B2: 1 | C2: 1
A3: Race | B3: 1 | C3: 1
A4: Batman v Superman: Dawn of Justice | B4: 1 | C4: 1
A5: The Boss | B5: 1 | C5: 1
A6: Captain America: Civil War | B6: 1 | C6: 1
A7: Neighbors 2: Sorority Rising | B7: 1 | C7: 1
A8: The Nice Guys | B8: 1 | C8: 1
A9: Popstar: Never Stop Never Stopping | B9: 1 | C9: 1
A10: Now You See Me 2 | B10: 1 | C10: 1
A11: Pixar's Finding Dory | B11: 1 | C11: 1
A12: The Shallows | B12: 1 | C12: 1
A13: The Legend of Tarzan | B13: 1 | C13: 1
... A36: Free State of Jones | B36: 1 | C36: 1
A37: The 5th Wave | C37: 1
A38: Dirty Grandpa | C38: 1
A39: Hail, Caesar! | C39: 1
A40: Zoolander 2 | C40: 1
A41: Eddie the Eagle | C41: 1
A42: The Jungle Book | C42: 1
A43: X-Men: Apocalypse | C43: 1
A44: Me Before You | C44: 1
A45: Central Intelligence | C45: 1
A46: Don't Think Twice | C46: 1
A47: The Light Between Oceans | C47: 1
A48: Sully | C48: 1
... A66: Hidden Figures | C66: 1
A67: Kung Fu Panda 3 | D67: 1
A68: The Witch | D68: 1
A69: London Has Fallen | D69: 1
A70: Whiskey Tango Foxtrot | D70: 1
A71: Zootopia | D71: 1
A72: The Brothers Grimsby | D72: 1
A73: The Lobster | D73: 1
A74: The Divergent Series: Allegiant | D74: 1
A75: The Bronze | D75: 1
A76: Everybody Wants Some!! | D76: 1
A77: Elvis & Nixon | D77: 1
A78: The Huntsman: Winter's War | D78: 1
... A111: The Do-Over | D111: 1
...

Sheet 2015
B1: Seen | C1: Own | D1: Want to see | E1: Where | F1: IMDb | G1: =SUM(B:B) -> 26 | H1: =_xlfn.CONCAT(SUM(C:C)," (",SUMPRODUCT(C:C,--(NOT(B:B=1))),")") -> 47 (24)
A2: What We Do in the Shadows | B2: 1 | C2: 1
A3: Get Hard | B3: 1 | C3: 1
A4: Ex Machina | B4: 1 | C4: 1
A5: Avengers: Age of Ultron | B5: 1 | C5: 1
A6: San Andreas | B6: 1 | C6: 1
A7: Spy | B7: 1 | C7: 1
A8: Jurassic World | B8: 1 | C8: 1
A9: Minions | B9: 1 | C9: 1
A10: Ant-Man | B10: 1 | C10: 1
A11: Trainwreck | B11: 1 | C11: 1
A12: Southpaw | B12: 1 | C12: 1
A13: Black Mass | B13: 1 | C13: 1
... A24: Point Break | B24: 1 | C24: 1
A25: Vacation | B25: 1 | D25: 1
A26: Vice | B26: 1
A27: Hot Pursuit | B27: 1
A28: Home | C28: 1
A29: Mad Max: Fury Road | C29: 1
A30: Pitch Perfect 2 | C30: 1
A31: Aloha | C31: 1
A32: Max | C32: 1
A33: Ted 2 | C33: 1
A34: Terminator: Genisys | C34: 1
A35: The Stanford Prison Experiment | C35: 1
A36: Mission: Impossible - Rogue Nation | C36: 1
A37: Everest | C37: 1
A38: Hotel Transylvania 2 | C38: 1
A39: Room | C39: 1
... A51: Where to Invade Next | C51: 1
A52: Paddington | D52: 1
A53: Hot Tub Time Machine 2 | D53: 1
A54: Chappie | D54: 1
A55: Cinderella | D55: 1
A56: The Cobbler | D56: 1
A57: Divergent Series: Insurgent | D57: 1
A58: Entourage | D58: 1
A59: Me and Earl and the Dying Girl | D59: 1
A60: Dope | D60: 1
A61: The Man From U.N.C.L.E. | D61: 1
...

Sheet 2014
B1: Seen | C1: Own | D1: Want to see | E1: Where | F1: IMDb | G1: =SUM(B:B) -> 16 | H1: =_xlfn.CONCAT(SUM(C:C)," (",SUMPRODUCT(C:C,--(NOT(B:B=1))),")") -> 39 (25)
A2: The LEGO Movie | B2: 1 | C2: 1
A3: Captain America: The Winter Soldier | B3: 1 | C3: 1
A4: Neighbors | B4: 1 | C4: 1
A5: Godzilla | B5: 1 | C5: 1
A6: Sex Tape | B6: 1 | C6: 1
A7: Guardians of the Galaxy | B7: 1 | C7: 1
A8: Gone Girl | B8: 1 | C8: 1
A9: The Judge | B9: 1 | C9: 1
A10: John Wick | B10: 1 | C10: 1
A11: Interstellar | B11: 1 | C11: 1
A12: The Hunger Games: Mockingjay Part 1 | B12: 1 | C12: 1
A13: The Imitation Game | B13: 1 | C13: 1
... A15: Horrible Bosses 2 | B15: 1 | C15: 1
A16: Tammy | B16: 1
A17: Lucy | B17: 1
A18: That Awkward Moment | C18: 1
A19: 300: Rise of an Empire | C19: 1
A20: The Grand Budapest Hotel | C20: 1
A21: Draft Day | C21: 1
A22: Rio 2 | C22: 1
A23: X-Men: Days of Future Past | C23: 1
A24: Dawn of the Planet of the Apes | C24: 1
A25: Let's Be Cops | C25: 1
A26: The Equalizer | C26: 1
A27: St. Vincent | C27: 1
A28: Whiplash | C28: 1
A29: Birdman | C29: 1
... A42: The Gambler | C42: 1
A43: Jack Ryan: Shadow Recruit | D43: 1
A44: I, Frankenstein | D44: 1
A45: RoboCop | D45: 1
A46: Mr. Peabody & Sherman | D46: 1
A47: Veronica Mars | D47: 1
A48: Divergent | D48: 1
A49: Muppets Most Wanted | D49: 1
A50: Chef | D50: 1
A51: Million Dollar Arm | D51: 1
A52: Maleficent | D52: 1
A53: A Million Ways to Die in the West | D53: 1
...

Sheet 2013
B1: Seen | C1: Own | D1: Want to see | E1: Where | F1: IMDb | G1: =SUM(B:B) -> 15 | H1: =_xlfn.CONCAT(SUM(C:C)," (",SUMPRODUCT(C:C,--(NOT(B:B=1))),")") -> 41 (29) | I1: Wikipedia
A2: 42 | B2: 1 | C2: 1
A3: Iron Man 3 | B3: 1 | C3: 1
A4: Now You See Me | B4: 1 | C4: 1
A5: The Internship | B5: 1 | C5: 1
A6: Despicable Me 2 | B6: 1 | C6: 1
A7: Kick-Ass 2 | B7: 1 | C7: 1
A8: 12 Years a Slave | B8: 1 | C8: 1
A9: Thor: The Dark World | B9: 1 | C9: 1
A10: The Hunger Games: Catching Fire | B10: 1 | C10: 1
A11: Anchorman 2: The Legend Continues | B11: 1 | C11: 1
A12: The Wolf of Wall Street | B12: 1 | C12: 1
A13: In a World | B13: 1 | C13: 1
A14: Monsters University | B14: 1
A15: Delivery Man | B15: 1
A16: Frozen | B16: 1
A17: A Good Day to Die Hard | C17: 1
A18: The Incredible Burt Wonderstone | C18: 1
A19: Mud | C19: 1
A20: The Great Gatsby | C20: 1
A21: This Is the End | C21: 1
A22: Man of Steel | C22: 1
A23: The Heat | C23: 1
A24: White House Down | C24: 1
A25: Bad Words | C25: 1
A26: Blue Jasmine | C26: 1
A27: The Wolverine | C27: 1
A28: We're the Millers | C28: 1
... A45: The Butler | C45: 1
A46: John Dies at the End | D46: 1
A47: Spring Breakers | D47: 1
A48: Stoker | D48: 1
A49: The Croods | D49: 1
A50: Evil Dead | D50: 1
A51: The English Teacher | D51: 1
A52: Frances Ha | D52: 1
A53: Before Midnight | D53: 1
A54: World War Z | D54: 1
A55: Fruitvale Station | D55: 1
A56: Pacific Rim | D56: 1
...

Sheet 2012
B1: Seen | C1: Own | D1: Want to see | E1: Where | F1: IMDb | G1: =SUM(B:B) -> 9 | H1: =_xlfn.CONCAT(SUM(C:C)," (",SUMPRODUCT(C:C,--(NOT(B:B=1))),")") -> 36 (28) | I1: Wikipedia
A2: The Hunger Games | B2: 1 | C2: 1
A3: The Avengers | B3: 1 | C3: 1
A4: Men in Black 3 | B4: 1 | C4: 1
A5: Argo | B5: 1 | C5: 1
A6: Django Unchained | B6: 1 | C6: 1
A7: The Dark Knight Rises | B7: 1 | C7: 1
A8: Silver Linings Playbook | B8: 1 | C8: 1
A9: The Bay | B9: 1 | C9: 1
A10: Wreck-It Ralph | B10: 1
A11: 21 Jump Street | C11: 1
A12: American Reunion | C12: 1
A13: Snow White and the Huntsman | C13: 1
A14: Prometheus | C14: 1
A15: Seeking a Friend for the End of the World | C15: 1
A16: Ted | C16: 1
A17: Ice Age: Continental Drift | C17: 1
A18: The Watch | C18: 1
A19: Total Recall | C19: 1
A20: The Campaign | C20: 1
A21: Trouble with the Curve | C21: 1
A22: Hotel Transylvania | C22: 1
... A38: Jack Reacher | C38: 1
A39: Casa de Mi Padre | D39: 1
A40: Jeff, Who Lives at Home | D40: 1
A41: Goon | D41: 1
A42: Moonrise Kingdom | D42: 1
A43: The Amazing Spider-Man | D43: 1
A44: The Bourne Legacy | D44: 1
A45: ParaNorman | D45: 1
A46: Anna Karenina | D46: 1
A47: The Perks of Being a Wallflower | D47: 1
A48: Frankenweenie | D48: 1
A49: Seven Psychopaths | D49: 1
A50: Sinister | D50: 1
... A52: Les Misérables | D52: 1
A53: The Devil Inside
A54: Beneath the Darkness
A55: Norwegian Wood
A56: Contraband
...

Sheet 2011
B1: Seen | C1: Own | D1: Want to see | E1: Where | F1: IMDb | G1: =SUM(B:B) -> 9 | H1: =_xlfn.CONCAT(SUM(C:C)," (",SUMPRODUCT(C:C,--(NOT(B:B=1))),")") -> 40 (31) | I1: Wikipedia
A2: The Green Hornet | B2: 1 | C2: 1
A3: Thor | B3: 1 | C3: 1
A4: Bridesmaids | B4: 1 | C4: 1
A5: Pirates of the Caribbean: On Stranger Tides | B5: 1 | C5: 1
A6: Green Lantern | B6: 1 | C6: 1
A7: Horrible Bosses | B7: 1 | C7: 1
A8: Harry Potter and the Deathly Hallows – Part 2 | B8: 1 | C8: 1
A9: Captain America: The First Avenger | B9: 1 | C9: 1
A10: Sherlock Holmes: A Game of Shadows | B10: 1 | C10: 1
A11: Just Go with It | C11: 1
A12: Take Me Home Tonight | C12: 1
A13: Soul Surfer | C13: 1
A14: Rio | C14: 1
A15: The Hangover Part II | C15: 1
A16: X-Men: First Class | C16: 1
A17: Friends with Benefits | C17: 1
A18: The Smurfs | C18: 1
A19: Rise of the Planet of the Apes | C19: 1
A20: The Help | C20: 1
A21: Moneyball | C21: 1
A22: J. Edgar | C22: 1
... A41: The Iron Lady | C41: 1
A42: Cedar Rapids | D42: 1
A43: Hall Pass | D43: 1
A44: The Lincoln Lawyer | D44: 1
A45: Paul | D45: 1
A46: Insidious | D46: 1
A47: Bad Teacher | D47: 1
A48: Warrior | D48: 1
A49: Drive | D49: 1
A50: Tinker Tailor Soldier Spy | D50: 1
A51: We Need to Talk About Kevin | D51: 1
A52: War Horse | D52: 1
A53: Phil Ochs: There but for Fortune
A54: Season of the Witch
A55: The Time That Remains
A56: Barney's Version
A57: The Dilemma
A58: No Strings Attached
...

Sheet 2010
B1: Seen | C1: Own | D1: Want to see | E1: Where | F1: IMDb | G1: =SUM(B:B) -> 0 | H1: =_xlfn.CONCAT(SUM(C:C)," (",SUMPRODUCT(C:C,--(NOT(B:B=1))),")") -> 0 (0) | I1: Wikipedia

Sheet Streaming
A2: Hulu | B2: =SUMPRODUCT('2023'!$F$1:$F$997,--('2023'!$E$1:$E$997=Streaming!$A2)/COUNTIF('2023'!$E$1:$E$997,Streaming!$A2)) -> 5.7405405 | C2: =COUNTIF('2023'!$E$1:$E$997,Streaming!$A2) -> 74
A3: Netflix | B3: =SUMPRODUCT('2023'!$F$1:$F$997,--('2023'!$E$1:$E$997=Streaming!$A3)/COUNTIF('2023'!$E$1:$E$997,Streaming!$A3)) -> 6.0595238 | C3: =COUNTIF('2023'!$E$1:$E$997,Streaming!$A3) -> 84
A4: Max | B4: =SUMPRODUCT('2023'!$F$1:$F$997,--('2023'!$E$1:$E$997=Streaming!$A4)/COUNTIF('2023'!$E$1:$E$997,Streaming!$A4)) -> 6.63 | C4: =COUNTIF('2023'!$E$1:$E$997,Streaming!$A4) -> 10
A5: Apple | B5: =SUMPRODUCT('2023'!$F$1:$F$997,--('2023'!$E$1:$E$997=Streaming!$A5)/COUNTIF('2023'!$E$1:$E$997,Streaming!$A5)) -> 6.8333333 | C5: =COUNTIF('2023'!$E$1:$E$997,Streaming!$A5) -> 9
